#VRML_SIM R2023b utf8

EXTERNPROTO "https://raw.githubusercontent.com/cyberbotics/webots/R2023b/projects/objects/backgrounds/protos/TexturedBackground.proto"
EXTERNPROTO "https://raw.githubusercontent.com/cyberbotics/webots/R2023b/projects/objects/backgrounds/protos/TexturedBackgroundLight.proto"
EXTERNPROTO "https://raw.githubusercontent.com/cyberbotics/webots/R2023b/projects/objects/floors/protos/RectangleArena.proto"

WorldInfo {
}
Viewpoint {
  orientation -0.0856111709547801 -0.3699698043762642 0.9250908448674326 5.793001146002487
  position -2.303439073294066 0.878966860625591 1.051125954887157
}
TexturedBackground {
}
TexturedBackgroundLight {
}
RectangleArena {
  floorSize 10 10
}
Robot {
  translation 0 0 0.1
  children [
    DEF BaseJoint HingeJoint {
      jointParameters HingeJointParameters {
        axis 0 0 1
        anchor 0 0 0.15
      }
      device [
        DEF BaseMotor RotationalMotor {
          name "base_motor"
          minPosition -3.14159
          maxPosition 3.14159
        }
      ]
      endPoint Solid {
        translation 0 0 0.15
        children [
          DEF ShoulderJoint HingeJoint {
            jointParameters HingeJointParameters {
              anchor 0.05 0 0
            }
            device [
              RotationalMotor {
                name "shoulder_motor"
                minPosition -3.14159
                maxPosition 3.14159
              }
            ]
            endPoint Solid {
              translation 0.05 0 0
              rotation 1 0 0 0
              children [
                Solid {
                  translation 0.03 0 0.12
                  children [
                    HingeJoint {
                      jointParameters HingeJointParameters {
                        anchor -0.03 0 0.125
                      }
                      device [
                        RotationalMotor {
                          name "elbow_motor"
                          minPosition -3.14159
                          maxPosition 3.14159
                        }
                      ]
                      endPoint Solid {
                        translation -0.03 0 0.125
                        rotation 1 0 0 0
                        children [
                          Solid {
                            translation -0.03 0 0.075
                            children [
                              HingeJoint {
                                jointParameters HingeJointParameters {
                                  anchor 0.03 0 0.075
                                }
                                device [
                                  RotationalMotor {
                                    name "forearm_motor"
                                    minPosition -3.14159
                                    maxPosition 3.14159
                                  }
                                ]
                                endPoint Solid {
                                  translation 0.03 0 0.075
                                  rotation 1 0 0 0
                                  children [
                                    Solid {
                                      translation 0.03 0 0.05
                                      children [
                                        HingeJoint {
                                          jointParameters HingeJointParameters {
                                            axis 0 0 1
                                            anchor 0 0 0.08
                                          }
                                          device [
                                            RotationalMotor {
                                              name "wrist_motor"
                                              minPosition -3.14159
                                              maxPosition 3.14159
                                            }
                                          ]
                                          endPoint Solid {
                                            translation 0 0 0.08
                                            children [
                                              Solid {
                                                translation 0 0 0.03
                                                children [
                                                  DEF gripper Solid {
                                                    children [
                                                      Shape {
                                                        appearance DEF BLACK_METAL PBRAppearance {
                                                          baseColor 0 0 0
                                                          roughness 0.4
                                                          metalness 0
                                                        }
                                                        geometry Mesh {
                                                          url [
                                                            "https://raw.githubusercontent.com/cyberbotics/webots/R2023b/projects/devices/robotiq/protos/meshes/robotiq_base_link.stl"
                                                          ]
                                                        }
                                                      }
                                                      HingeJoint {
                                                        jointParameters HingeJointParameters {
                                                          axis -1 0 0
                                                          anchor 0 -0.030601 0.054905
                                                          minStop -0.01
                                                          maxStop 0.701
                                                          dampingConstant 0.03
                                                        }
                                                        device [
                                                          RotationalMotor {
                                                            name "ROBOTIQ 2F-140 Gripper::left finger joint"
                                                            maxVelocity 2
                                                            maxPosition 0.7
                                                            maxTorque 0.12
                                                          }
                                                          PositionSensor {
                                                            name "ROBOTIQ 2F-140 Gripper left finger joint sensor"
                                                          }
                                                        ]
                                                        endPoint Solid {
                                                          translation 1.1102230246251208e-16 -0.03060099999999968 0.054905000000001085
                                                          rotation 1 3.043697299531194e-17 -7.60924324882799e-17 2.2957959986997842
                                                          children [
                                                            DEF OUTER_KNUCKLE Shape {
                                                              appearance PBRAppearance {
                                                                baseColorMap ImageTexture {
                                                                  url [
                                                                    "https://raw.githubusercontent.com/cyberbotics/webots/R2023b/projects/appearances/protos/textures/brushed_aluminium/brushed_aluminium_base_color.jpg"
                                                                  ]
                                                                }
                                                                roughnessMap ImageTexture {
                                                                  url [
                                                                    "https://raw.githubusercontent.com/cyberbotics/webots/R2023b/projects/appearances/protos/textures/brushed_aluminium/brushed_aluminium_roughness.jpg"
                                                                  ]
                                                                }
                                                                normalMap ImageTexture {
                                                                  url [
                                                                    "https://raw.githubusercontent.com/cyberbotics/webots/R2023b/projects/appearances/protos/textures/brushed_aluminium/brushed_aluminium_normal.jpg"
                                                                  ]
                                                                }
                                                                textureTransform TextureTransform {
                                                                  scale 3 5
                                                                }
                                                              }
                                                              geometry Mesh {
                                                                url [
                                                                  "https://raw.githubusercontent.com/cyberbotics/webots/R2023b/projects/devices/robotiq/protos/meshes/robotiq_2f140_outer_knuckle.stl"
                                                                ]
                                                              }
                                                            }
                                                            Solid {
                                                              translation 0 0.01822 0.026002
                                                              children [
                                                                DEF OUTER_FINGER Shape {
                                                                  appearance USE BLACK_METAL
                                                                  geometry Mesh {
                                                                    url [
                                                                      "https://raw.githubusercontent.com/cyberbotics/webots/R2023b/projects/devices/robotiq/protos/meshes/robotiq_2f140_outer_finger.stl"
                                                                    ]
                                                                  }
                                                                }
                                                                HingeJoint {
                                                                  jointParameters HingeJointParameters {
                                                                    anchor 0 0.081755 -0.02822
                                                                  }
                                                                  endPoint Solid {
                                                                    translation 8.326672684688504e-17 0.0817549999999988 -0.028219999999998732
                                                                    rotation -1 -6.261605892851442e-16 -1.5654014732128768e-16 0.724999999999815
                                                                    children [
                                                                      DEF INNER_FINGER Shape {
                                                                        appearance USE BLACK_METAL
                                                                        geometry Mesh {
                                                                          url [
                                                                            "https://raw.githubusercontent.com/cyberbotics/webots/R2023b/projects/devices/robotiq/protos/meshes/robotiq_2f140_inner_finger.stl"
                                                                          ]
                                                                        }
                                                                      }
                                                                      Solid {
                                                                        translation 0 0.045755 -0.02722
                                                                        rotation 1 0 0 -0.01
                                                                        children [
                                                                          DEF INNER_FINGER_PAD Shape {
                                                                            appearance USE BLACK_METAL
                                                                            geometry Box {
                                                                              size 0.027 0.065 0.0075
                                                                            }
                                                                          }
                                                                        ]
                                                                        name "left inner finger pad"
                                                                        contactMaterial "ROBOTIQ gripper pad"
                                                                        boundingObject DEF INNER_FINGER_PAD_BO Box {
                                                                          size 0.03 0.07 0.0075
                                                                        }
                                                                        physics Physics {
                                                                        }
                                                                      }
                                                                    ]
                                                                    name "ROBOTIQ 2F-140 Gripper left inner finger"
                                                                    boundingObject DEF INNER_FINGER_BO Group {
                                                                      children [
                                                                        Pose {
                                                                          translation 0 0.021 -0.018
                                                                          children [
                                                                            Box {
                                                                              size 0.015 0.047 0.012
                                                                            }
                                                                          ]
                                                                        }
                                                                        Pose {
                                                                          translation 0 0.003 -0.008
                                                                          rotation 1 0 0 -1.2
                                                                          children [
                                                                            Box {
                                                                              size 0.015 0.029 0.012
                                                                            }
                                                                          ]
                                                                        }
                                                                      ]
                                                                    }
                                                                    physics Physics {
                                                                      density -1
                                                                      mass 0.0104
                                                                      centerOfMass [
                                                                        0.0003 0.016008 -0.013695
                                                                      ]
                                                                    }
                                                                  }
                                                                }
                                                              ]
                                                              name "left outer finger"
                                                              boundingObject DEF OUTER_FINGER_BO Group {
                                                                children [
                                                                  Pose {
                                                                    translation 0 0.0511 -0.02
                                                                    rotation 1 0 0 -0.2618
                                                                    children [
                                                                      Box {
                                                                        size 0.025 0.074 0.012
                                                                      }
                                                                    ]
                                                                  }
                                                                  Pose {
                                                                    translation 0 0.006 -0.004
                                                                    rotation -1 0 0 -2.56
                                                                    children [
                                                                      Box {
                                                                        size 0.025 0.026 0.012
                                                                      }
                                                                    ]
                                                                  }
                                                                ]
                                                              }
                                                              physics Physics {
                                                                density -1
                                                                mass 0.022614
                                                                centerOfMass [
                                                                  0.000301 0.037391 -0.020803
                                                                ]
                                                              }
                                                            }
                                                          ]
                                                          name "left outer knuckle"
                                                          boundingObject DEF OUTER_KNUCKLE_BO Group {
                                                            children [
                                                              Pose {
                                                                translation 0 0.002 0.004
                                                                rotation 1 0 0 0.9
                                                                children [
                                                                  Box {
                                                                    size 0.009 0.063 0.012
                                                                  }
                                                                ]
                                                              }
                                                              Pose {
                                                                translation 0 0.0209 0.019
                                                                rotation 1 0 0 0.95
                                                                children [
                                                                  Box {
                                                                    size 0.009 0.02 0.02
                                                                  }
                                                                ]
                                                              }
                                                              Pose {
                                                                rotation 0 1 0 1.5708
                                                                children [
                                                                  Cylinder {
                                                                    height 0.017
                                                                    radius 0.004
                                                                  }
                                                                ]
                                                              }
                                                              Pose {
                                                                translation 0 0.0218 0.0136
                                                                rotation 0 1 0 1.5708
                                                                children [
                                                                  Cylinder {
                                                                    height 0.024
                                                                    radius 0.003
                                                                  }
                                                                ]
                                                              }
                                                            ]
                                                          }
                                                          physics Physics {
                                                            density -1
                                                            mass 0.008532
                                                            centerOfMass [
                                                              -0.0002 0.019944 0.029225
                                                            ]
                                                          }
                                                        }
                                                      }
                                                      HingeJoint {
                                                        jointParameters HingeJointParameters {
                                                          anchor 0 -0.0127 0.06142
                                                        }
                                                        endPoint Solid {
                                                          translation -2.775557561562836e-17 -0.012699999999999632 0.06142000000000025
                                                          rotation 0.9999999999999999 -2.891512433708683e-16 1.5218486493203714e-17 2.2957959999999122
                                                          children [
                                                            DEF INNER_KNUCKLE Shape {
                                                              appearance USE BLACK_METAL
                                                              geometry Mesh {
                                                                url [
                                                                  "https://raw.githubusercontent.com/cyberbotics/webots/R2023b/projects/devices/robotiq/protos/meshes/robotiq_2f140_inner_knuckle.stl"
                                                                ]
                                                              }
                                                            }
                                                            HingeJoint {
                                                              jointParameters HingeJointParameters {
                                                                anchor 0 0.1 -0.002
                                                              }
                                                              endPoint SolidReference {
                                                                solidName "ROBOTIQ 2F-140 Gripper left inner finger"
                                                              }
                                                            }
                                                          ]
                                                          name "left inner knuckle"
                                                          boundingObject DEF INNER_KNUCKLE_BO Group {
                                                            children [
                                                              Pose {
                                                                rotation 0 1 0 1.5708
                                                                children [
                                                                  Cylinder {
                                                                    height 0.0394
                                                                    radius 0.0059
                                                                  }
                                                                ]
                                                              }
                                                              Pose {
                                                                translation -0.0158 0.018 -0.0003
                                                                rotation 1 0 0 -0.02
                                                                children [
                                                                  Box {
                                                                    size 0.007 0.038 0.0121
                                                                  }
                                                                ]
                                                              }
                                                              Pose {
                                                                translation 0.0158 0.018 -0.0003
                                                                rotation 1 0 0 -0.02
                                                                children [
                                                                  Box {
                                                                    size 0.007 0.038 0.0121
                                                                  }
                                                                ]
                                                              }
                                                              Pose {
                                                                translation 0 0.0677 -0.0013
                                                                rotation 1 0 0 -0.02
                                                                children [
                                                                  Box {
                                                                    size 0.0246 0.076 0.0121
                                                                  }
                                                                ]
                                                              }
                                                              Pose {
                                                                translation 0.0035 0.101 -0.0023
                                                                rotation 0 1 0 1.5708
                                                                children [
                                                                  Cylinder {
                                                                    height 0.032
                                                                    radius 0.0058
                                                                  }
                                                                ]
                                                              }
                                                            ]
                                                          }
                                                          physics Physics {
                                                            density -1
                                                            mass 0.027118
                                                            centerOfMass [
                                                              0.000123 0.050785 0.00104
                                                            ]
                                                          }
                                                        }
                                                      }
                                                      HingeJoint {
                                                        jointParameters HingeJointParameters {
                                                          anchor 0 0.030601 0.054905
                                                          minStop -0.01
                                                          maxStop 0.701
                                                          dampingConstant 0.03
                                                        }
                                                        device [
                                                          RotationalMotor {
                                                            name "ROBOTIQ 2F-140 Gripper::right finger joint"
                                                            maxVelocity 2
                                                            maxPosition 0.7
                                                            maxTorque 0.12
                                                          }
                                                          PositionSensor {
                                                            name "ROBOTIQ 2F-140 Gripper right finger joint sensor"
                                                          }
                                                        ]
                                                        endPoint Solid {
                                                          translation -2.7755575615628248e-17 0.030601000000000184 0.054905000000000086
                                                          rotation 4.063218387543446e-17 -0.911903298415477 -0.41040513439645665 3.1415923071795864
                                                          children [
                                                            USE OUTER_KNUCKLE
                                                            Solid {
                                                              translation 0 0.01822 0.026002
                                                              children [
                                                                USE OUTER_FINGER
                                                                HingeJoint {
                                                                  jointParameters HingeJointParameters {
                                                                    anchor 0 0.081755 -0.0282
                                                                  }
                                                                  endPoint Solid {
                                                                    translation 2.7755575615628174e-16 0.08175499999999958 -0.0282199999999996
                                                                    rotation -1 -6.8877664820863495e-15 -3.835233609343555e-15 0.7249999999996836
                                                                    children [
                                                                      USE INNER_FINGER
                                                                      Solid {
                                                                        translation 0 0.045755 -0.02722
                                                                        rotation 1 0 0 -0.01
                                                                        children [
                                                                          USE INNER_FINGER_PAD
                                                                        ]
                                                                        name "right inner finger pad"
                                                                        contactMaterial "ROBOTIQ gripper pad"
                                                                        boundingObject USE INNER_FINGER_PAD_BO
                                                                        physics Physics {
                                                                        }
                                                                      }
                                                                    ]
                                                                    name "ROBOTIQ 2F-140 Gripper right inner finger"
                                                                    boundingObject USE INNER_FINGER_BO
                                                                    physics Physics {
                                                                      density -1
                                                                      mass 0.0104
                                                                      centerOfMass [
                                                                        0.0003 0.016008 -0.013695
                                                                      ]
                                                                    }
                                                                  }
                                                                }
                                                              ]
                                                              name "right outer finger"
                                                              boundingObject USE OUTER_FINGER_BO
                                                              physics Physics {
                                                                density -1
                                                                mass 0.022614
                                                                centerOfMass [
                                                                  0.000301 0.037391 -0.020803
                                                                ]
                                                              }
                                                            }
                                                          ]
                                                          name "right outer knuckle"
                                                          boundingObject USE OUTER_KNUCKLE_BO
                                                          physics Physics {
                                                            density -1
                                                            mass 0.008532
                                                            centerOfMass [
                                                              -0.0002 0.019944 0.029225
                                                            ]
                                                          }
                                                        }
                                                      }
                                                      HingeJoint {
                                                        jointParameters HingeJointParameters {
                                                          axis -1 0 0
                                                          anchor 0 0.0127 0.06142
                                                        }
                                                        endPoint Solid {
                                                          translation 0 0.0127 0.06142
                                                          rotation -1.23617481960065e-16 -0.911903298450497 -0.4104051343186438 3.141593
                                                          children [
                                                            USE INNER_KNUCKLE
                                                            HingeJoint {
                                                              jointParameters HingeJointParameters {
                                                                anchor 0 0.1 -0.002
                                                              }
                                                              endPoint SolidReference {
                                                                solidName "ROBOTIQ 2F-140 Gripper right inner finger"
                                                              }
                                                            }
                                                          ]
                                                          name "right inner knuckle"
                                                          boundingObject USE INNER_KNUCKLE_BO
                                                          physics Physics {
                                                            density -1
                                                            mass 0.027118
                                                            centerOfMass [
                                                              0.000123 0.050785 0.00104
                                                            ]
                                                          }
                                                        }
                                                      }
                                                    ]
                                                    name "ROBOTIQ 2F-140 Gripper"
                                                    boundingObject Group {
                                                      children [
                                                        Pose {
                                                          translation 0 0 0.018
                                                          children [
                                                            Cylinder {
                                                              height 0.036
                                                              radius 0.0375
                                                            }
                                                          ]
                                                        }
                                                        Pose {
                                                          translation 0 0 0.055
                                                          rotation 0 1 0 1.5708
                                                          children [
                                                            Cylinder {
                                                              height 0.023
                                                              radius 0.04
                                                            }
                                                          ]
                                                        }
                                                      ]
                                                    }
                                                  }
                                                  DEF wrist Shape {
                                                    appearance PBRAppearance {
                                                    }
                                                    geometry Box {
                                                      size 0.05 0.05 0.05
                                                    }
                                                  }
                                                ]
                                                boundingObject USE wrist
                                              }
                                              Shape {
                                                appearance PBRAppearance {
                                                  baseColor 1 0 1
                                                }
                                                geometry Box {
                                                  size 0.05 0.05 0.01
                                                }
                                              }
                                            ]
                                          }
                                        }
                                        DEF forearm Shape {
                                          appearance PBRAppearance {
                                            baseColor 1 1 0
                                          }
                                          geometry Box {
                                            size 0.05 0.05 0.15
                                          }
                                        }
                                      ]
                                      boundingObject USE forearm
                                    }
                                    Shape {
                                      appearance PBRAppearance {
                                        baseColor 1 0 1
                                      }
                                      geometry Box {
                                        size 0.01 0.05 0.05
                                      }
                                    }
                                  ]
                                }
                              }
                              Shape {
                                appearance PBRAppearance {
                                  baseColor 1 1 0
                                }
                                geometry Box {
                                  size 0.05 0.05 0.2
                                }
                              }
                            ]
                          }
                          Shape {
                            appearance PBRAppearance {
                              baseColor 1 0 1
                            }
                            geometry Box {
                              size 0.01 0.05 0.05
                            }
                          }
                        ]
                      }
                    }
                    Shape {
                      appearance PBRAppearance {
                        baseColor 1 1 0
                      }
                      geometry Box {
                        size 0.05 0.05 0.3
                      }
                    }
                  ]
                }
                Shape {
                  appearance PBRAppearance {
                    baseColor 1 0 1
                  }
                  geometry Box {
                    size 0.01 0.1 0.1
                  }
                }
              ]
              name "solid(1)"
            }
          }
          Shape {
            appearance PBRAppearance {
              baseColor 0 1 1
            }
            geometry Box {
              size 0.1 0.1 0.1
            }
          }
        ]
      }
    }
    Pose {
      children [
        DEF Base Shape {
          appearance PBRAppearance {
          }
          geometry Cylinder {
            height 0.2
            radius 0.05
          }
        }
      ]
    }
  ]
  boundingObject USE Base
  physics Physics {
  }
  controller "BlockArm"
}
